Workbook

Sheet Summary
A1: MASTERCARD FINANCIAL MODEL – EXECUTIVE SUMMARY
A2: (All figures in USD Millions unless stated otherwise)
A3: Company Overview:
A4: Company Name | B4: Mastercard Inc
A5: Industry | B5: Payment Technology
A6: Forecast Period | B6: 2025-2029
A7: Valuation Methods | B7: DCF,FCFF,DDM,Relative Valuation
A8: Shares Outstanding | B8: ='Profit Loss'!F24 -> 927
A9: Current Share Price | B9: =B52 -> 450
A10: Market Capitalization | B10: =B8*B9 -> 417150
A12: Valuation Multiples | B12: 2024
A13: Enterprise Value | B13: =B22 -> 417150
A14: P/E Ratio | B14: =B9/B32 -> 32.397408
A15: EV/EBITDA | B15: =B13/'Profit Loss'!F25 -> 25.314036
A16: Price / Book | B16: =B9/B17 -> 64.029163
A17: Book Value Per Share | B17: =Balance_Sheet!F41/'Profit Loss'!F24 -> 7.0280475
A19: Key Valuation Summary
A20: Metric | B20: Value
A21: Market Cap | B21: =B10 -> 417150
A22: Enterprise Value | B22: =B10 -> 417150
A23: P/E | B23: =B14 -> 32.397408
A24: EV/EBITDA | B24: =B15 -> 25.314036
A25: Target Price | B25: =B53 -> 378.19635
A26: Upside / Downside | B26: =B54 -> -0.15956367
A28: Financial Highlights
A29: Metric | B29: 2024 | C29: 2025E | D29: 2026E | E29: 2027E | F29: 2028E | G29: 2029E
A30: Revenue | B30: ='Profit Loss'!F4 -> 28167 | C30: ='Profit Loss'!G4 -> 31265.37 | D30: ='Profit Loss'!H4 -> 34391.907 | E30: ='Profit Loss'!I4 -> 37487.179 | F30: ='Profit Loss'!J4 -> 40486.153 | G30: ='Profit Loss'!K4 -> 43320.184
A31: Net Profit | B31: ='Profit Loss'!F20 -> 12874 | C31: ='Profit Loss'!G20 -> 14041.325 | D31: ='Profit Loss'!H20 -> 15786.104 | E31: ='Profit Loss'!I20 -> 17411.45 | F31: ='Profit Loss'!J20 -> 19017.164 | G31: ='Profit Loss'!K20 -> 20568.896
A32: EPS | B32: ='Profit Loss'!F23 -> 13.89 | C32: ='Profit Loss'!G23 -> 15.456184 | D32: ='Profit Loss'!H23 -> 17.731402 | E32: ='Profit Loss'!I23 -> 19.95616 | F32: ='Profit Loss'!J23 -> 22.241379 | G32: ='Profit Loss'!K23 -> 24.547138
A33: Operating Margin | B33: ='Profit Loss'!F26 -> 0.55320055 | C33: ='Profit Loss'!G26 -> 0.55 | D33: ='Profit Loss'!H26 -> 0.56 | E33: ='Profit Loss'!I26 -> 0.565 | F33: ='Profit Loss'!J26 -> 0.57 | G33: ='Profit Loss'!K26 -> 0.575
A35: Growth & Profitability
A36: Key Insights
A37: Revenue CAGR | B37: ='CAGR Projections'!G4 -> 0.16481028
A38: EPS CAGR | B38: ='CAGR Projections'!G7 -> 0.21419038
A39: Average ROE | B39: =AVERAGE(Ratios!C13:G13) -> 1.4616261
A40: Average Operating Margin | B40: =AVERAGE(Ratios!C41:G41) -> 0.54497449
A42: Final Investment Recommendation
A43: Method | B43: Target Price | C43: Weight | D43: Weighted Value
A44: FCFE | B44: ='DDM FCFF Relative Valuation'!B106 -> 338.00514 | C44: 0.25 | D44: =B44*C44 -> 84.501285
A45: DDM | B45: ='DDM FCFF Relative Valuation'!B15 -> 66.395914 | C45: 0.05 | D45: =B45*C45 -> 3.3197957
...

Sheet Assumptions
A1: Income Statement | D1: Key Forecast Assumptions – Mastercard Financial Model
A2: Assumption | B2: Value | D2: Assumption | E2: Value | F2: Basis
A3: Cash % of Revenue | B3: 0.15 | D3: Revenue Growth | E3: 0.1 | F3: Historical Trend
A4: Accounts Receivable % of Revenue | B4: 0.0117 | D4: Tax Rate | E4: 0.16 | F4: Effective Tax Rate
A5: Settlement Assets % of Revenue | B5: 0.134 | D5: Opex | E5: 0.45 | F5: 3-Year Average
A6: Prepaid Assets % of Revenue | B6: 0.106
A7: PPE Growth Rate | B7: 0.04 | E7: Capital Allocation Assumptions | F7: Value
A8: Intangibles Growth Rate | B8: 0.03 | E8: Dividend Payout Ratio | F8: 0.3
A9: Accrued Exp % of Revenue | B9: 0.369 | E9: Share Buyback % | F9: 0.02
D11: Opex Expansion Model | E11: Operating expenses decline due to operating leverage and automation efficiency.
A12: Balance Sheet | D12: Year | E12: Opex %
A13: Assumption | B13: Value | D13: 2025 | E13: 0.45
A14: Revenue Growth 2025E | B14: 0.11 | D14: 2026 | E14: 0.44
A15: Revenue Growth 2026E | B15: 0.1 | D15: 2027 | E15: 0.435
A16: Revenue Growth 2027E | B16: 0.09 | D16: 2028 | E16: 0.43
A17: Revenue Growth 2028E | B17: 0.08 | D17: 2029 | E17: 0.425
A18: Revenue Growth 2029E | B18: 0.07
A19: Total Opex % of Revenue | B19: 0.45
A20: Other Income % | B20: -0.01
A21: Tax Rate | B21: 0.16
A22: Cost of Debt | B22: 0.045
A24: Assumption | B24: Value
A25: Revenue CAGR | B25: 0.15
A26: G&A Growth | B26: 0.35
A27: Marketing % of Revenue | B27: 0.03
A28: Depreciation Growth | B28: 0.03
A29: Litigation Growth | B29: 0.05
A30: Investment Income Growth | B30: 0.04
A31: Interest Expense Growth | B31: 0.03
A32: Tax Rate | B32: 0.16
A33: Share Buyback | B33: 0.04
A35: Working Capital Assumption | B35: Value
A36: Accounts Receivable Growth | B36: 0.0117
A37: Settlement Assets Growth | B37: 0.134
A38: Prepaid Assets Growth | B38: 0.08
A39: Accounts Payable Growth | B39: 0.033
A40: Accrued Expenses Growth | B40: 0.369
A41: Other Assets Growth | B41: 0.3535

Sheet WACC
A1: WACC Calculation | B1: Column1
A2: A | B2: B
A3: Cost of Equity (CAPM)
A4: Risk Free Rate | B4: =Table43[[#This Row],[Column1]] -> 0.045
A5: Market Return | B5: =Table43[[#This Row],[Column1]] -> 0.1
A6: Beta | B6: {=Table23[Value]} -> 1.0378473
A7: Cost of Equity | B7: =B4+B6*(B5-B4) -> 0.1020816
A8: Cost of Debt
A9: A | B9: B
A10: Cost of Debt
A11: Interest Expense | B11: 820.17
A12: Total Debt | B12: =Balance_Sheet!G28+Balance_Sheet!G25 -> 18226
A13: Cost of Debt | B13: =B11/B12 -> 0.045
A14: A | B14: B
A15: Capital Structure
A16: Market Price | B16: 450
A17: Shares Outstanding | B17: ='Profit Loss'!K24 -> 837.93458
A18: Market Cap | B18: =B16*B17 -> 377070.56
A19: Total Debt | B19: =B12 -> 18226
A20: Enterprise Value | B20: =B18+B19 -> 395296.56
A21: Capital Weights
A22: A | B22: B
A23: Equity Weight | B23: =B18/B20 -> 0.95389284
A24: Debt Weight | B24: =B19/B20 -> 0.046107156
A25: WACC
A26: A | B26: B
A27: Tax Rate | B27: ='DCF Valuation'!B7 -> 0.16
A28: WACC | B28: =(B23*B7)+(B24*B13*(1-B27)) -> 0.09911776
A30: Sources
A31: Input | B31: Value | C31: Source
A32: Risk Free Rate | B32: 0.042 | C32: US 10Y Treasury
A33: Market Return | B33: 0.1 | C33: Long-term S&P500
A34: Beta | B34: 1.03 | C34: Yahoo Finance

Sheet CAGR Projections
A1: CAGR Projections
A2: Income Statement CAGR Projection
A3: Item | B3: 2020 | C3: 2021 | D3: 2022 | E3: 2023 | F3: 2024 | G3: CAGR | H3: 2025 | I3: 2026 | J3: 2027 | K3: 2028 | L3: 2029
A4: Revenue | B4: =Table1[[#This Row],[2020]] -> 15301 | C4: =Table1[[#This Row],[2021]] -> 18884 | D4: =Table1[[#This Row],[2022]] -> 22237 | E4: =Table1[[#This Row],[2023]] -> 25098 | F4: =Table1[[#This Row],[2024]] -> 28167 | G4: =(Table51[[#This Row],[2024]] / Table51[[#This Row],[2020]])^(1/4)-1 -> 0.16481028 | H4: =F4*(1+$G4) -> 32809.211 | I4: =Table51[[#This Row],[2025]]*(1+Table51[[#This Row],[CAGR]]) -> 38216.506 | J4: =Table51[[#This Row],[2026]]*(1+Table51[[#This Row],[CAGR]]) -> 44514.98 | K4: =Table51[[#This Row],[2027]]*(1+Table51[[#This Row],[CAGR]]) -> 51851.506 | L4: =Table51[[#This Row],[2028]]*(1+Table51[[#This Row],[CAGR]]) -> 60397.167
A5: Operating Income | B5: ='Profit Loss'!B11 -> 8081 | C5: ='Profit Loss'!C11 -> 10082 | D5: ='Profit Loss'!D11 -> 12264 | E5: ='Profit Loss'!E11 -> 14008 | F5: ='Profit Loss'!F11 -> 15582 | G5: =(Table51[[#This Row],[2024]] / Table51[[#This Row],[2020]])^(1/4)-1 -> 0.17839129 | H5: =F5*(1+$G5) -> 18361.693 | I5: =Table51[[#This Row],[2025]]*(1+Table51[[#This Row],[CAGR]]) -> 21637.259 | J5: =Table51[[#This Row],[2026]]*(1+Table51[[#This Row],[CAGR]]) -> 25497.158 | K5: =Table51[[#This Row],[2027]]*(1+Table51[[#This Row],[CAGR]]) -> 30045.629 | L5: =Table51[[#This Row],[2028]]*(1+Table51[[#This Row],[CAGR]]) -> 35405.507
A6: Net Income | B6: ='Profit Loss'!B20 -> 6411 | C6: ='Profit Loss'!C20 -> 8687 | D6: ='Profit Loss'!D20 -> 9930 | E6: ='Profit Loss'!E20 -> 11195 | F6: ='Profit Loss'!F20 -> 12874 | G6: =(Table51[[#This Row],[2024]] / Table51[[#This Row],[2020]])^(1/4)-1 -> 0.190411 | H6: =F6*(1+$G6) -> 15325.351 | I6: =Table51[[#This Row],[2025]]*(1+Table51[[#This Row],[CAGR]]) -> 18243.467 | J6: =Table51[[#This Row],[2026]]*(1+Table51[[#This Row],[CAGR]]) -> 21717.223 | K6: =Table51[[#This Row],[2027]]*(1+Table51[[#This Row],[CAGR]]) -> 25852.422 | L6: =Table51[[#This Row],[2028]]*(1+Table51[[#This Row],[CAGR]]) -> 30775.007
A7: EPS | B7: ='Profit Loss'!B21 -> 6.4 | C7: ='Profit Loss'!C21 -> 8.79 | D7: ='Profit Loss'!D21 -> 10.26 | E7: ='Profit Loss'!E21 -> 11.86 | F7: ='Profit Loss'!F21 -> 13.91 | G7: =(Table51[[#This Row],[2024]] / Table51[[#This Row],[2020]])^(1/4)-1 -> 0.21419038 | H7: =F7*(1+$G7) -> 16.889388 | I7: =Table51[[#This Row],[2025]]*(1+Table51[[#This Row],[CAGR]]) -> 20.506933 | J7: =Table51[[#This Row],[2026]]*(1+Table51[[#This Row],[CAGR]]) -> 24.899321 | K7: =Table51[[#This Row],[2027]]*(1+Table51[[#This Row],[CAGR]]) -> 30.232516 | L7: =Table51[[#This Row],[2028]]*(1+Table51[[#This Row],[CAGR]]) -> 36.70803
A9: Balance Sheet CAGR Projection
A10: Item | B10: 2020 | C10: 2021 | D10: 2022 | E10: 2023 | F10: 2024 | G10: CAGR | H10: 2025 | I10: 2026 | J10: 2027 | K10: 2028 | L10: 2029
A11: Total Assets | B11: =Balance_Sheet!B18 -> 33584 | C11: =Balance_Sheet!C18 -> 37669 | D11: =Balance_Sheet!D18 -> 38724 | E11: =Balance_Sheet!E18 -> 42448 | F11: =Balance_Sheet!F18 -> 48081 | G11: =(Table52[[#This Row],[2024]] / Table52[[#This Row],[2020]])^(1/4)-1 -> 0.093856288 | H11: =F11*(1+$G11) -> 52593.704 | I11: =Table52[[#This Row],[2025]]*(1+Table52[[#This Row],[CAGR]]) -> 57529.954 | J11: =Table52[[#This Row],[2026]]*(1+Table52[[#This Row],[CAGR]]) -> 62929.502 | K11: =Table52[[#This Row],[2027]]*(1+Table52[[#This Row],[CAGR]]) -> 68835.831 | L11: =Table52[[#This Row],[2028]]*(1+Table52[[#This Row],[CAGR]]) -> 75296.507
A12: Total Liabilities | B12: =Balance_Sheet!B31 -> 27067 | C12: =Balance_Sheet!C31 -> 30257 | D12: =Balance_Sheet!D31 -> 32347 | E12: =Balance_Sheet!E31 -> 35451 | F12: =Balance_Sheet!F31 -> 41566 | G12: =(Table52[[#This Row],[2024]] / Table52[[#This Row],[2020]])^(1/4)-1 -> 0.11320341 | H12: =F12*(1+$G12) -> 46271.413 | I12: =Table52[[#This Row],[2025]]*(1+Table52[[#This Row],[CAGR]]) -> 51509.495 | J12: =Table52[[#This Row],[2026]]*(1+Table52[[#This Row],[CAGR]]) -> 57340.545 | K12: =Table52[[#This Row],[2027]]*(1+Table52[[#This Row],[CAGR]]) -> 63831.69 | L12: =Table52[[#This Row],[2028]]*(1+Table52[[#This Row],[CAGR]]) -> 71057.655
A13: Shareholders Equity | B13: =Balance_Sheet!B41 -> 6488 | C13: =Balance_Sheet!C41 -> 7383 | D13: =Balance_Sheet!D41 -> 6356 | E13: =Balance_Sheet!E41 -> 6975 | F13: =Balance_Sheet!F41 -> 6515 | G13: =(Table52[[#This Row],[2024]] / Table52[[#This Row],[2020]])^(1/4)-1 -> 0.0010387626 | H13: =F13*(1+$G13) -> 6521.7675 | I13: =Table52[[#This Row],[2025]]*(1+Table52[[#This Row],[CAGR]]) -> 6528.5421 | J13: =Table52[[#This Row],[2026]]*(1+Table52[[#This Row],[CAGR]]) -> 6535.3237 | K13: =Table52[[#This Row],[2027]]*(1+Table52[[#This Row],[CAGR]]) -> 6542.1124 | L13: =Table52[[#This Row],[2028]]*(1+Table52[[#This Row],[CAGR]]) -> 6548.9081
A14: Cash & Cash Equivalents | B14: =Balance_Sheet!B4 -> 10113 | C14: =Balance_Sheet!C4 -> 7421 | D14: =Balance_Sheet!D4 -> 7008 | E14: =Balance_Sheet!E4 -> 8588 | F14: =Balance_Sheet!F4 -> 8442 | G14: =(Table52[[#This Row],[2024]] / Table52[[#This Row],[2020]])^(1/4)-1 -> -0.044146499 | H14: =F14*(1+$G14) -> 8069.3153 | I14: =Table52[[#This Row],[2025]]*(1+Table52[[#This Row],[CAGR]]) -> 7713.0832 | J14: =Table52[[#This Row],[2026]]*(1+Table52[[#This Row],[CAGR]]) -> 7372.5776 | K14: =Table52[[#This Row],[2027]]*(1+Table52[[#This Row],[CAGR]]) -> 7047.1041 | L14: =Table52[[#This Row],[2028]]*(1+Table52[[#This Row],[CAGR]]) -> 6735.9991
A16: Cash Flow Statement CAGR Projection
A17: Item | B17: 2020 | C17: 2021 | D17: 2022 | E17: 2023 | F17: 2024 | G17: CAGR | H17: 2025 | I17: 2026 | J17: 2027 | K17: 2028 | L17: 2029
A18: Operating Cash Flow | B18: ='Cash Flow'!B24 -> 7224 | C18: ='Cash Flow'!C24 -> 9463 | D18: ='Cash Flow'!D24 -> 11195 | E18: ='Cash Flow'!E24 -> 11980 | F18: ='Cash Flow'!F24 -> 14780 | G18: =(Table53[[#This Row],[2024]] / Table53[[#This Row],[2020]])^(1/4)-1 -> 0.19598071 | H18: =F18*(1+$G18) -> 17676.595 | I18: =Table53[[#This Row],[2025]]*(1+Table53[[#This Row],[CAGR]]) -> 21140.866 | J18: =Table53[[#This Row],[2026]]*(1+Table53[[#This Row],[CAGR]]) -> 25284.068 | K18: =Table53[[#This Row],[2027]]*(1+Table53[[#This Row],[CAGR]]) -> 30239.258 | L18: =Table53[[#This Row],[2028]]*(1+Table53[[#This Row],[CAGR]]) -> 36165.569
A19: Investing Cash Flow | B19: ='Cash Flow'!B38 -> -1879 | C19: ='Cash Flow'!C38 -> -5272 | D19: ='Cash Flow'!D38 -> -1470 | E19: ='Cash Flow'!E38 -> -1351 | F19: ='Cash Flow'!F38 -> -3402 | G19: =(Table53[[#This Row],[2024]] / Table53[[#This Row],[2020]])^(1/4)-1 -> 0.15998369 | H19: =AVERAGE(Table53[[#This Row],[2020]:[2024]]) -> -2674.8 | I19: =AVERAGE(Table53[[#This Row],[2020]:[2024]]) -> -2674.8 | J19: =AVERAGE(Table53[[#This Row],[2020]:[2024]]) -> -2674.8 | K19: =AVERAGE(Table53[[#This Row],[2020]:[2024]]) -> -2674.8 | L19: =AVERAGE(Table53[[#This Row],[2020]:[2024]]) -> -2674.8
A20: Financing Cash Flow | B20: ='Cash Flow'!B50 -> -2152 | C20: ='Cash Flow'!C50 -> -6555 | D20: ='Cash Flow'!D50 -> -10328 | E20: ='Cash Flow'!E50 -> -9488 | F20: ='Cash Flow'!F50 -> -10836 | G20: =(Table53[[#This Row],[2024]] / Table53[[#This Row],[2020]])^(1/4)-1 -> 0.4979823 | H20: =AVERAGE(Table53[[#This Row],[2020]:[2024]]) -> -7871.8 | I20: =AVERAGE(Table53[[#This Row],[2020]:[2024]]) -> -7871.8 | J20: =AVERAGE(Table53[[#This Row],[2020]:[2024]]) -> -7871.8 | K20: =AVERAGE(Table53[[#This Row],[2020]:[2024]]) -> -7871.8 | L20: =AVERAGE(Table53[[#This Row],[2020]:[2024]]) -> -7871.8
A21: Free Cash Flow | B21: ='Cash Flow'!B55 -> 7563 | C21: ='Cash Flow'!C55 -> 9870 | D21: ='Cash Flow'!D55 -> 11637 | E21: ='Cash Flow'!E55 -> 12351 | F21: ='Cash Flow'!F55 -> 15254 | G21: =(Table53[[#This Row],[2024]] / Table53[[#This Row],[2020]])^(1/4)-1 -> 0.19171501 | H21: =F21*(1+$G21) -> 18178.421 | I21: =Table53[[#This Row],[2025]]*(1+Table53[[#This Row],[CAGR]]) -> 21663.497 | J21: =Table53[[#This Row],[2026]]*(1+Table53[[#This Row],[CAGR]]) -> 25816.715 | K21: =Table53[[#This Row],[2027]]*(1+Table53[[#This Row],[CAGR]]) -> 30766.166 | L21: =Table53[[#This Row],[2028]]*(1+Table53[[#This Row],[CAGR]]) -> 36664.502

Sheet Profit Loss
A1: Consolidated Statement of Operations - USD ($) shares in Millions, $ in Millions | B1: 2020 | C1: 2021 | D1: 2022 | E1: 2023 | F1: 2024 | G1: 2025E | H1: 2026E | I1: 2027E | J1: 2028E | K1: 2029E
A2: Mastercard Inc | M2: 2020-2024 | N2: Historicals
A3: Income Statement [Abstract] | M3: 2025-2029 | N3: Projections
A4: Net revenue | B4: 15301 | C4: 18884 | D4: 22237 | E4: 25098 | F4: 28167 | G4: =Table1[[#This Row],[2024]]*(1+Assumptions!B14) -> 31265.37 | H4: =Table1[[#This Row],[2025E]]*(1+Assumptions!B15) -> 34391.907 | I4: =Table1[[#This Row],[2026E]]*(1+Assumptions!B16) -> 37487.179 | J4: =Table1[[#This Row],[2027E]]*(1+Assumptions!B17) -> 40486.153 | K4: =Table1[[#This Row],[2028E]]*(1+Assumptions!B18) -> 43320.184
A5: Operating Expenses
A6: General and administrative | B6: 5910 | C6: 7087 | D6: 8078 | E6: 8927 | F6: 10193 | G6: =Table1[[#This Row],[2024]]*1.08 -> 11008.44 | H6: =Table1[[#This Row],[2025E]]*1.08 -> 11889.115 | I6: =Table1[[#This Row],[2026E]]*1.08 -> 12840.244 | J6: =Table1[[#This Row],[2027E]]*1.08 -> 13867.464 | K6: =Table1[[#This Row],[2028E]]*1.08 -> 14976.861
A7: Advertising and marketing | B7: 657 | C7: 895 | D7: 789 | E7: 825 | F7: 815 | G7: =G4*3% -> 937.9611 | H7: =H4*3% -> 1031.7572 | I7: =I4*3% -> 1124.6154 | J7: =J4*3% -> 1214.5846 | K7: =K4*3% -> 1299.6055
A8: Depreciation and amortization | B8: 580 | C8: 726 | D8: 750 | E8: 799 | F8: 897 | G8: =Table1[[#This Row],[2024]]*1.08 -> 968.76 | H8: =Table1[[#This Row],[2025E]]*1.08 -> 1046.2608 | I8: =Table1[[#This Row],[2026E]]*1.08 -> 1129.9617 | J8: =Table1[[#This Row],[2027E]]*1.08 -> 1220.3586 | K8: =Table1[[#This Row],[2028E]]*1.08 -> 1317.9873
A9: Provision for litigation | B9: 73 | C9: 94 | D9: 356 | E9: 539 | F9: 680 | G9: =Table1[[#This Row],[2024]]*1.05 -> 714 | H9: =Table1[[#This Row],[2025E]]*1.05 -> 749.7 | I9: =Table1[[#This Row],[2026E]]*1.05 -> 787.185 | J9: =Table1[[#This Row],[2027E]]*1.05 -> 826.54425 | K9: =Table1[[#This Row],[2028E]]*1.05 -> 867.87146
A10: Total operating expenses | B10: 7220 | C10: 8802 | D10: 9973 | E10: 11090 | F10: 12585 | G10: =G4*Assumptions!E13 -> 14069.417 | H10: =H4*Assumptions!E14 -> 15132.439 | I10: =I4*Assumptions!E15 -> 16306.923 | J10: =J4*Assumptions!E16 -> 17409.046 | K10: =K4*Assumptions!E17 -> 18411.078
A11: Operating income | B11: 8081 | C11: 10082 | D11: 12264 | E11: 14008 | F11: 15582 | G11: =(G4-G10) -> 17195.954 | H11: =(H4-H10) -> 19259.468 | I11: =(I4-I10) -> 21180.256 | J11: =(J4-J10) -> 23077.107 | K11: =(K4-K10) -> 24909.106
A12: Other Income (Expense)
A13: Investment income | B13: 24 | C13: 11 | D13: 61 | E13: 274 | F13: 327 | G13: =Table1[[#This Row],[2024]]*(1+Assumptions!B30) -> 340.08 | H13: =Table1[[#This Row],[2025E]]*(1+Assumptions!B30) -> 353.6832 | I13: =Table1[[#This Row],[2026E]]*(1+Assumptions!B30) -> 367.83053 | J13: =Table1[[#This Row],[2027E]]*(1+Assumptions!B30) -> 382.54375 | K13: =Table1[[#This Row],[2028E]]*(1+Assumptions!B30) -> 397.8455
A14: Gains (losses) on equity investments, net | B14: 30 | C14: 645 | D14: -145 | E14: -61 | F14: -29 | G14: 0 | H14: 0 | I14: 0 | J14: 0 | K14: 0
A15: Interest expense | B15: -380 | C15: -431 | D15: -471 | E15: -575 | F15: -646 | G15: =-'Common Size'!G43*Assumptions!B22 -> -820.17 | H15: =-'Common Size'!H43*Assumptions!B22 -> -820.17 | I15: =-'Common Size'!I43*Assumptions!B22 -> -820.17 | J15: =-'Common Size'!J43*Assumptions!B22 -> -820.17 | K15: =-'Common Size'!K43*Assumptions!B22 -> -820.17
A16: Other income (expense), net | B16: 5 | C16: 0 | D16: 23 | E16: -7 | F16: 20 | G16: 0 | H16: =Table1[[#This Row],[2025E]]*(1+Assumptions!B31) -> 0 | I16: =Table1[[#This Row],[2026E]]*(1+Assumptions!B31) -> 0 | J16: =Table1[[#This Row],[2027E]]*(1+Assumptions!B31) -> 0 | K16: =Table1[[#This Row],[2028E]]*(1+Assumptions!B31) -> 0
A17: Total other income (expense) | B17: -321 | C17: 225 | D17: -532 | E17: -369 | F17: -328 | G17: =G13+G14+G15+G16 -> -480.09 | H17: =SUM(H13:H16) -> -466.4868 | I17: =SUM(I13:I16) -> -452.33947 | J17: =SUM(J13:J16) -> -437.62625 | K17: =SUM(K13:K16) -> -422.3245
A18: Income before income taxes | B18: 7760 | C18: 10307 | D18: 11732 | E18: 13639 | F18: 15254 | G18: =G11+G17 -> 16715.864 | H18: =H11+H17 -> 18792.981 | I18: =I11+I17 -> 20727.916 | J18: =J11+J17 -> 22639.481 | K18: =K11+K17 -> 24486.781
A19: Income tax expense | B19: 1349 | C19: 1620 | D19: 1802 | E19: 2444 | F19: 2380 | G19: =G18*16% -> 2674.5382 | H19: =H18*16% -> 3006.877 | I19: =I18*16% -> 3316.4666 | J19: =J18*16% -> 3622.3169 | K19: =K18*16% -> 3917.885
A20: Net Income | B20: 6411 | C20: 8687 | D20: 9930 | E20: 11195 | F20: 12874 | G20: =G18-G19 -> 14041.325 | H20: =H18-H19 -> 15786.104 | I20: =I18-I19 -> 17411.45 | J20: =J18-J19 -> 19017.164 | K20: =K18-K19 -> 20568.896
A21: Basic Earnings per Share | B21: 6.4 | C21: 8.79 | D21: 10.26 | E21: 11.86 | F21: 13.91 | G21: =G20/G22 -> 15.489603 | H21: =H20/H22 -> 17.76974 | I21: =I20/I22 -> 19.999308 | J21: =J20/J22 -> 22.289469 | K21: =K20/K22 -> 24.600213
A22: Basic weighted-average shares outstanding | B22: 1002 | C22: 988 | D22: 968 | E22: 944 | F22: 925 | G22: =Table1[[#This Row],[2024]]*(1-2%) -> 906.5 | H22: =Table1[[#This Row],[2025E]]*(1-Assumptions!F9) -> 888.37 | I22: =Table1[[#This Row],[2026E]]*(1-Assumptions!F9) -> 870.6026 | J22: =Table1[[#This Row],[2027E]]*(1-Assumptions!F9) -> 853.19055 | K22: =Table1[[#This Row],[2028E]]*(1-Assumptions!F9) -> 836.12674
A23: Diluted Earnings per Share | B23: 6.37 | C23: 8.76 | D23: 10.22 | E23: 11.83 | F23: 13.89 | G23: =G20/G24 -> 15.456184 | H23: =H20/H24 -> 17.731402 | I23: =I20/I24 -> 19.95616 | J23: =J20/J24 -> 22.241379 | K23: =K20/K24 -> 24.547138
A24: Diluted weighted-average shares outstanding | B24: 1006 | C24: 992 | D24: 971 | E24: 946 | F24: 927 | G24: =Table1[[#This Row],[2024]]*(1-Assumptions!F9) -> 908.46 | H24: =Table1[[#This Row],[2025E]]*(1-Assumptions!F9) -> 890.2908 | I24: =Table1[[#This Row],[2026E]]*(1-Assumptions!F9) -> 872.48498 | J24: =Table1[[#This Row],[2027E]]*(1-Assumptions!F9) -> 855.03528 | K24: =Table1[[#This Row],[2028E]]*(1-Assumptions!F9) -> 837.93458
A25: EBITDA | B25: =B11+B8 -> 8661 | C25: =C11+C8 -> 10808 | D25: =D11+D8 -> 13014 | E25: =E11+E8 -> 14807 | F25: =F11+F8 -> 16479 | G25: =G11+G8 -> 18164.714 | H25: =H11+H8 -> 20305.729 | I25: =I11+I8 -> 22310.218 | ... K25: =K11+K8 -> 26227.093
A26: Operating Margin | B26: =B11/B4 -> 0.52813542 | C26: =C11/C4 -> 0.53389112 | D26: =D11/D4 -> 0.55151324 | E26: =E11/E4 -> 0.55813212 | F26: =F11/F4 -> 0.55320055 | G26: =G11/G4 -> 0.55 | H26: =H11/H4 -> 0.56 | I26: =I11/I4 -> 0.565 | ... K26: =K11/K4 -> 0.575
A27: Net Margin | B27: =B20/B4 -> 0.41899222 | C27: =C20/C4 -> 0.46001906 | D27: =D20/D4 -> 0.44655304 | E27: =E20/E4 -> 0.44605148 | F27: =F20/F4 -> 0.45705968 | G27: =G20/G4 -> 0.44910152 | H27: =H20/H4 -> 0.45900636 | I27: =I20/I4 -> 0.46446413 | ... K27: =K20/K4 -> 0.47481092

Sheet Balance_Sheet
A1: Consolidated Balance Sheet - USD ($) $ in Millions | B1: 2020 | C1: 2021 | D1: 2022 | E1: 2023 | F1: 2024 | G1: 2025E | H1: 2026E | I1: 2027E | J1: 2028E | K1: 2029E
A2: Mastercard Inc | M2: 2020-2024 | N2: Historicals
A3: Assets | M3: 2025-2029 | N3: Projections
A4: Cash and cash equivalents | B4: 10113 | C4: 7421 | D4: 7008 | E4: 8588 | F4: 8442 | G4: ='Cash Flow'!G54 -> 13504.262 | H4: ='Cash Flow'!H54 -> 18359.463 | I4: ='Cash Flow'!I54 -> 23602.217 | J4: ='Cash Flow'!J54 -> 29153.571 | K4: ='Cash Flow'!K54 -> 34906.025
A5: Restricted cash for litigation settlement | B5: 586 | C5: 586 | D5: 589 | E5: 32 | F5: 492 | G5: 492 | H5: 492 | I5: 492 | J5: 492 | K5: 492
A6: Investments | B6: 483 | C6: 473 | D6: 400 | E6: 1845 | F6: 1874 | G6: 1874 | H6: 1874 | I6: 1874 | J6: 1874 | K6: 1874
A7: Accounts receivable | B7: 2646 | C7: 3006 | D7: 3425 | E7: 592 | F7: 330 | G7: ='Profit Loss'!G4*Assumptions!B36 -> 365.80483 | H7: ='Profit Loss'!H4*Assumptions!B36 -> 402.38531 | I7: ='Profit Loss'!I4*Assumptions!B36 -> 438.59999 | J7: ='Profit Loss'!J4*Assumptions!B36 -> 473.68799 | K7: ='Profit Loss'!K4*Assumptions!B36 -> 506.84615
A8: Settlement assets | B8: 1706 | C8: 1319 | D8: 1270 | E8: 4060 | F8: 3773 | G8: ='Profit Loss'!G4*Assumptions!B37 -> 4189.5596 | H8: ='Profit Loss'!H4*Assumptions!B37 -> 4608.5155 | I8: ='Profit Loss'!I4*Assumptions!B37 -> 5023.2819 | J8: ='Profit Loss'!J4*Assumptions!B37 -> 5425.1445 | K8: ='Profit Loss'!K4*Assumptions!B37 -> 5804.9046
A9: Restricted security deposits held for customers | B9: 1696 | C9: 1873 | D9: 1568 | E9: 1233 | F9: 1821 | G9: 1821 | H9: 1821 | I9: 1821 | J9: 1821 | K9: 1821
A10: Prepaid expenses and other current assets | B10: 1883 | C10: 2271 | D10: 2346 | E10: 2611 | F10: 2992 | G10: ='Profit Loss'!G4*Assumptions!B38 -> 2501.2296 | H10: ='Profit Loss'!H4*Assumptions!B38 -> 2751.3526 | I10: ='Profit Loss'!I4*Assumptions!B38 -> 2998.9743 | J10: ='Profit Loss'!J4*Assumptions!B38 -> 3238.8922 | K10: ='Profit Loss'!K4*Assumptions!B38 -> 3465.6147
A11: Total current assets | B11: =SUM(B4:B10) -> 19113 | C11: =SUM(C4:C10) -> 16949 | D11: =SUM(D4:D10) -> 16606 | E11: =SUM(E4:E10) -> 18961 | F11: =SUM(F4:F10) -> 19724 | G11: =SUM(G4:G10) -> 24747.856 | H11: =SUM(H4:H10) -> 30308.716 | I11: =SUM(I4:I10) -> 36250.074 | ... K11: =SUM(K4:K10) -> 48870.39
A12: Property, equipment and right-of-use assets, net | B12: 1902 | C12: 1907 | D12: 2006 | E12: 2061 | F12: 2138 | G12: =Table2[[#This Row],[2024]]*(1+Assumptions!B7) -> 2223.52 | H12: =Table2[[#This Row],[2025E]]*(1+Assumptions!B7) -> 2312.4608 | I12: =Table2[[#This Row],[2026E]]*(1+Assumptions!B7) -> 2404.9592 | J12: =Table2[[#This Row],[2027E]]*(1+Assumptions!B7) -> 2501.1576 | K12: =Table2[[#This Row],[2028E]]*(1+Assumptions!B7) -> 2601.2039
A13: Deferred income taxes | B13: 491 | C13: 486 | D13: 1151 | E13: 1355 | F13: 1614 | G13: 1614 | H13: 1614 | I13: 1614 | J13: 1614 | K13: 1614
A14: Goodwill | B14: 4960 | C14: 7662 | D14: 7522 | E14: 7660 | F14: 9193 | G14: 9193 | H14: 9193 | I14: 9193 | J14: 9193 | K14: 9193
A15: Other intangible assets, net | B15: 1753 | C15: 3671 | D15: 3859 | E15: 4086 | F15: 5453 | G15: =Table2[[#This Row],[2024]]*(1+Assumptions!B8) -> 5616.59 | H15: =Table2[[#This Row],[2025E]]*(1+Assumptions!B8) -> 5785.0877 | I15: =Table2[[#This Row],[2026E]]*(1+Assumptions!B8) -> 5958.6403 | J15: =Table2[[#This Row],[2027E]]*(1+Assumptions!B8) -> 6137.3995 | K15: =Table2[[#This Row],[2028E]]*(1+Assumptions!B8) -> 6321.5215
A16: Total Cash | B16: =B4+B5 -> 10699 | C16: =C4+C5 -> 8007 | D16: =D4+D5 -> 7597 | E16: =E4+E5 -> 8620 | F16: =F4+F5 -> 8934 | G16: =G4+G5 -> 13996.262 | H16: =H4+H5 -> 18851.463 | I16: =I4+I5 -> 24094.217 | ... K16: =K4+K5 -> 35398.025
A17: Other assets | B17: 5365 | C17: 6994 | D17: 7580 | E17: 8325 | F17: 9959 | G17: ='Profit Loss'!G4*Assumptions!B41 -> 11052.308 | H17: ='Profit Loss'!H4*Assumptions!B41 -> 12157.539 | I17: ='Profit Loss'!I4*Assumptions!B41 -> 13251.718 | J17: ='Profit Loss'!J4*Assumptions!B41 -> 14311.855 | K17: ='Profit Loss'!K4*Assumptions!B41 -> 15313.685
A18: Total Assets | B18: 33584 | C18: 37669 | D18: 38724 | E18: 42448 | F18: 48081 | G18: =G31+G41 -> 58699.683 | H18: =H31+H41 -> 70535.502 | I18: =I31+I41 -> 83458.48 | J18: =J31+J41 -> 97406.625 | K18: =K31+K41 -> 112292.29
A19: Liabilities, Redeemable Non-controlling Interests and Equity
A20: Accounts payable | B20: 527 | C20: 738 | D20: 926 | E20: 834 | F20: 929 | G20: ='Profit Loss'!G4*3.3% -> 1031.7572 | H20: ='Profit Loss'!H4*3.3% -> 1134.9329 | I20: ='Profit Loss'!I4*3.3% -> 1237.0769 | J20: ='Profit Loss'!J4*3.3% -> 1336.043 | K20: ='Profit Loss'!K4*3.3% -> 1429.5661
A21: Settlement obligations | B21: 1475 | C21: 913 | D21: 1111 | E21: 1399 | F21: 2316 | G21: ='Profit Loss'!G4*8.2% -> 2563.7603 | H21: ='Profit Loss'!H4*8.2% -> 2820.1364 | I21: ='Profit Loss'!I4*8.2% -> 3073.9486 | J21: ='Profit Loss'!J4*8.2% -> 3319.8645 | K21: ='Profit Loss'!K4*8.2% -> 3552.2551
A22: Restricted security deposits held for customers | B22: 1696 | C22: 1873 | D22: 1568 | E22: 1845 | F22: 1874 | G22: 1874 | H22: 1874 | I22: 1874 | J22: 1874 | K22: 1874
A23: Accrued litigation | B23: 842 | C23: 840 | D23: 1094 | E23: 723 | F23: 930 | G23: 930 | H23: 930 | I23: 930 | J23: 930 | K23: 930
A24: Accrued expenses | B24: 5430 | C24: 6642 | D24: 7801 | E24: 8517 | F24: 10393 | G24: ='Profit Loss'!G4*Assumptions!B40 -> 11536.922 | H24: ='Profit Loss'!H4*Assumptions!B40 -> 12690.614 | I24: ='Profit Loss'!I4*Assumptions!B40 -> 13832.769 | J24: ='Profit Loss'!J4*Assumptions!B40 -> 14939.39 | K24: ='Profit Loss'!K4*Assumptions!B40 -> 15985.148
A25: Current portion of long-term debt | B25: 649 | C25: 792 | D25: 274 | E25: 1337 | F25: 750 | G25: 750 | H25: 750 | I25: 750 | J25: 750 | K25: 750
A26: Other current liabilities | B26: 1228 | C26: 1364 | D26: 1397 | E26: 1609 | F26: 2028 | G26: ='Profit Loss'!G4*7.2% -> 2251.1066 | H26: ='Profit Loss'!H4*7.2% -> 2476.2173 | I26: ='Profit Loss'!I4*7.2% -> 2699.0769 | J26: ='Profit Loss'!J4*7.2% -> 2915.003 | K26: ='Profit Loss'!K4*7.2% -> 3119.0532
A27: Total current liabilities | B27: 11847 | C27: 13162 | D27: 14171 | E27: 16264 | F27: 19220 | G27: =SUM(G20:G26) -> 20937.546 | H27: =SUM(H20:H26) -> 22675.9 | I27: =SUM(I20:I26) -> 24396.871 | J27: =SUM(J20:J26) -> 26064.301 | K27: =SUM(K20:K26) -> 27640.022
A28: Long-term debt | B28: 12023 | C28: 13109 | D28: 13749 | E28: 14344 | F28: 17476 | G28: 17476 | H28: 17476 | I28: 17476 | J28: 17476 | K28: 17476
A29: Deferred income taxes | B29: 86 | C29: 395 | D29: 393 | E29: 369 | F29: 317 | G29: 317 | H29: 317 | I29: 317 | J29: 317 | K29: 317
A30: Other liabilities | B30: 3111 | C30: 3591 | D30: 4034 | E30: 4474 | F30: 4553 | G30: =Table2[[#This Row],[2024]]*(1+Assumptions!B14) -> 5053.83 | H30: =Table2[[#This Row],[2025E]]*(1+Assumptions!B15) -> 5559.213 | I30: =Table2[[#This Row],[2026E]]*(1+Assumptions!B16) -> 6059.5422 | J30: =Table2[[#This Row],[2027E]]*(1+Assumptions!B17) -> 6544.3055 | K30: =Table2[[#This Row],[2028E]]*(1+Assumptions!B18) -> 7002.4069
A31: Total Liabilities | B31: 27067 | C31: 30257 | D31: 32347 | E31: 35451 | F31: 41566 | G31: =G27+G28+G29+G30 -> 43784.376 | H31: =H27+H28+H29+H30 -> 46028.113 | I31: =I27+I28+I29+I30 -> 48249.413 | J31: =J27+J28+J29+J30 -> 50401.607 | K31: =K27+K28+K29+K30 -> 52435.429
A32: Commitments and Contingencies
A33: Redeemable non-controlling interests | B33: 29 | C33: 29 | D33: 21 | E33: 22 | F33: 0 | G33: 0 | H33: 0 | I33: 0 | J33: 0 | K33: 0
A34: Stockholders’ Equity
A35: Additional paid-in-capital | B35: 4982 | C35: 5061 | D35: 5298 | E35: 5893 | F35: 6442 | G35: 6442 | H35: 6442 | I35: 6442 | J35: 6442 | K35: 6442
A36: Class A treasury stock, at cost, 425 and 409 shares, respectively | B36: -36658 | C36: -42588 | D36: -51354 | E36: -60429 | F36: -71431 | G36: =Table2[[#This Row],[2024]]*1.02 -> -72859.62 | H36: =Table2[[#This Row],[2025E]]*1.02 -> -74316.812 | I36: =Table2[[#This Row],[2026E]]*1.02 -> -75803.149 | J36: =Table2[[#This Row],[2027E]]*1.02 -> -77319.212 | K36: =Table2[[#This Row],[2028E]]*1.02 -> -78865.596
A37: Retained earnings | B37: 38747 | C37: 45648 | D37: 53607 | E37: 62564 | F37: 72907 | G37: =Table2[[#This Row],[2024]]+'Profit Loss'!G20+'Cash Flow'!G41 -> 82735.928 | H37: =Table2[[#This Row],[2025E]]-1+'Profit Loss'!H20+'Cash Flow'!H41 -> 93785.201 | I37: =Table2[[#This Row],[2026E]]+'Profit Loss'!I20+'Cash Flow'!I41 -> 105973.22 | J37: =Table2[[#This Row],[2027E]]+'Profit Loss'!J20+'Cash Flow'!J41 -> 119285.23 | K37: =Table2[[#This Row],[2028E]]+'Profit Loss'!K20+'Cash Flow'!K41 -> 133683.46
A38: Accumulated other comprehensive income (loss) | B38: -680 | C38: -809 | D38: -1253 | E38: -1099 | F38: -1433 | G38: -1433 | H38: -1433 | I38: -1433 | J38: -1433 | K38: -1433
A39: Mastercard Incorporated Stockholders' Equity | B39: 6391 | C39: 7312 | D39: 6298 | E39: 6929 | F39: 6485 | G39: =G35+G37+G36+G38 -> 14885.308 | H39: =H35+H37+H36+H38 -> 24477.388 | I39: =I35+I37+I36+I38 -> 35179.067 | J39: =J35+J37+J36+J38 -> 46975.019 | K39: =K35+K37+K36+K38 -> 59826.862
A40: Non-controlling interests | B40: 97 | C40: 71 | D40: 58 | E40: 46 | F40: 30 | G40: 30 | H40: 30 | I40: 30 | J40: 30 | K40: 30
...

Sheet Cash Flow
A1: Consolidated Statement of Cash Flows - USD ($) $ in Millions | B1: 2020 | C1: 2021 | D1: 2022 | E1: 2023 | F1: 2024 | G1: 2025E | H1: 2026E | I1: 2027E | J1: 2028E | K1: 2029E
A2: Mastercard Inc | M2: 2020-2024 | N2: Historicals
A3: Operating Activities | M3: 2025-2029 | N3: Projections
A4: Net income | B4: 6411 | C4: 8687 | D4: 9930 | E4: 11195 | F4: 12874 | G4: ='Profit Loss'!G20 -> 14041.325 | H4: ='Profit Loss'!H20 -> 15786.104 | I4: ='Profit Loss'!I20 -> 17411.45 | J4: ='Profit Loss'!J20 -> 19017.164 | K4: ='Profit Loss'!K20 -> 20568.896
A5: Adjustments to reconcile net income to net cash provided by operating activities:
A6: Amortization of customer and merchant incentives | B6: 1072 | C6: 1371 | D6: 1586 | E6: 1622 | F6: 1830 | G6: =Table3[[#This Row],[2024]]*1.05 -> 1921.5 | H6: =Table3[[#This Row],[2025E]]*1.05 -> 2017.575 | I6: =Table3[[#This Row],[2026E]]*1.05 -> 2118.4538 | J6: =Table3[[#This Row],[2027E]]*1.05 -> 2224.3764 | K6: =Table3[[#This Row],[2028E]]*1.05 -> 2335.5953
A7: Depreciation and amortization | B7: 580 | C7: 726 | D7: 750 | E7: 799 | F7: 897 | G7: =Table3[[#This Row],[2024]]*1.06 -> 950.82 | H7: =Table3[[#This Row],[2025E]]*1.06 -> 1007.8692 | I7: =Table3[[#This Row],[2026E]]*1.06 -> 1068.3414 | J7: =Table3[[#This Row],[2027E]]*1.06 -> 1132.4418 | K7: =Table3[[#This Row],[2028E]]*1.06 -> 1200.3883
A8: (Gains) losses on equity investments, net | B8: -30 | C8: -645 | D8: 145 | E8: 61 | F8: 29 | G8: 29 | H8: 29 | I8: 29 | J8: 29 | K8: 29
A9: Share-based compensation | B9: 254 | C9: 273 | D9: 295 | E9: 460 | F9: 526 | G9: =Table3[[#This Row],[2024]]*1.06 -> 557.56 | H9: =Table3[[#This Row],[2025E]]*1.06 -> 591.0136 | I9: =Table3[[#This Row],[2026E]]*1.06 -> 626.47442 | J9: =Table3[[#This Row],[2027E]]*1.06 -> 664.06288 | K9: =Table3[[#This Row],[2028E]]*1.06 -> 703.90665
A10: Deferred income taxes | B10: 73 | C10: -69 | D10: -651 | E10: -236 | F10: -527 | G10: =Table3[[#This Row],[2024]]*1.03 -> -542.81 | H10: =Table3[[#This Row],[2025E]]*1.03 -> -559.0943 | I10: =Table3[[#This Row],[2026E]]*1.03 -> -575.86713 | J10: =Table3[[#This Row],[2027E]]*1.03 -> -593.14314 | K10: =Table3[[#This Row],[2028E]]*1.03 -> -610.93744
A11: Other | B11: 14 | C11: 36 | D11: 44 | E11: 22 | F11: 191 | G11: =Table3[[#This Row],[2024]]*1.03 -> 196.73 | H11: =Table3[[#This Row],[2025E]]*1.03 -> 202.6319 | I11: =Table3[[#This Row],[2026E]]*1.03 -> 208.71086 | J11: =Table3[[#This Row],[2027E]]*1.03 -> 214.97218 | K11: =Table3[[#This Row],[2028E]]*1.03 -> 221.42135
A12: Changes in operating assets and liabilities:
A13: Accounts receivable | B13: -86 | C13: -397 | D13: -481 | E13: -546 | F13: 186 | G13: =Balance_Sheet!F7-Balance_Sheet!G7 -> -35.804829 | H13: =Balance_Sheet!G7-Balance_Sheet!H7 -> -36.580483 | I13: =Balance_Sheet!H7-Balance_Sheet!I7 -> -36.214678 | J13: =Balance_Sheet!I7-Balance_Sheet!J7 -> -35.087999 | K13: =Balance_Sheet!J7-Balance_Sheet!K7 -> -33.158159
A14: Income taxes receivable | B14: -2 | C14: -87 | D14: 12 | E14: -171 | F14: -165 | G14: -165 | H14: -165 | I14: -165 | J14: -165 | K14: -165
A15: Settlement assets | B15: 1288 | C15: 390 | D15: 48 | E15: 40 | F15: -593 | G15: =Balance_Sheet!F8-Balance_Sheet!G8 -> -416.55958 | H15: =Balance_Sheet!G8-Balance_Sheet!H8 -> -418.95596 | I15: =Balance_Sheet!H8-Balance_Sheet!I8 -> -414.7664 | J15: =Balance_Sheet!I8-Balance_Sheet!J8 -> -401.86255 | K15: =Balance_Sheet!J8-Balance_Sheet!K8 -> -379.76011
A16: Prepaid expenses | B16: -1552 | C16: -2087 | D16: -2175 | E16: -2438 | F16: -3225 | G16: =Balance_Sheet!F10-Balance_Sheet!G10 -> 490.7704 | H16: =Balance_Sheet!G10-Balance_Sheet!H10 -> -250.12296 | I16: =Balance_Sheet!H10-Balance_Sheet!I10 -> -247.62173 | J16: =Balance_Sheet!I10-Balance_Sheet!J10 -> -239.91794 | K16: =Balance_Sheet!J10-Balance_Sheet!K10 -> -226.72246
A17: Accrued litigation and legal settlements | B17: -73 | C17: -1 | D17: 240 | E17: -375 | F17: 205 | G17: 205 | H17: 205 | I17: 205 | J17: 205 | K17: 205
A18: Restricted security deposits held for customers | B18: 326 | C18: 177 | D18: -305 | E18: 277 | F18: 29 | G18: 29 | H18: 29 | I18: 29 | J18: 29 | K18: 29
A19: Accounts payable | B19: 26 | C19: 100 | D19: 190 | E19: -99 | F19: 75 | G19: =(Balance_Sheet!G20-Balance_Sheet!F20)-1 -> 101.75721 | H19: =(Balance_Sheet!H20-Balance_Sheet!G20)-1 -> 102.17572 | I19: =(Balance_Sheet!I20-Balance_Sheet!H20)-1 -> 101.14396 | J19: =(Balance_Sheet!J20-Balance_Sheet!I20)-1 -> 97.966152 | K19: =(Balance_Sheet!K20-Balance_Sheet!J20)-1 -> 92.523013
A20: Settlement obligations | B20: -1242 | C20: -568 | D20: 201 | E20: 282 | F20: 922 | G20: 922 | H20: 922 | I20: 922 | J20: 922 | K20: 922
A21: Accrued expenses | B21: -114 | C21: 1355 | D21: 1188 | E21: 571 | F21: 1587 | G21: =Balance_Sheet!G24-Balance_Sheet!F24 -> 1143.9215 | H21: =Balance_Sheet!H24-Balance_Sheet!G24 -> 1153.6922 | I21: =Balance_Sheet!I24-Balance_Sheet!H24 -> 1142.1552 | J21: =Balance_Sheet!J24-Balance_Sheet!I24 -> 1106.6215 | K21: =Balance_Sheet!K24-Balance_Sheet!J24 -> 1045.7573
A22: Long-term taxes payable | B22: -37 | C22: -52 | D22: -121 | E22: -129 | F22: -163 | G22: -163 | H22: -163 | I22: -163 | J22: -163 | K22: -163
A23: Net change in other assets and liabilities | B23: 316 | C23: 254 | D23: 299 | E23: 645 | F23: 102 | G23: 102 | H23: 102 | I23: 102 | J23: 102 | K23: 102
A24: Net cash provided by operating activities | B24: 7224 | C24: 9463 | D24: 11195 | E24: 11980 | F24: 14780 | G24: =SUM(G4:G23) -> 19368.21 | H24: =SUM(H4:H23) -> 20555.308 | I24: =SUM(I4:I23) -> 22361.259 | J24: =SUM(J4:J23) -> 24146.593 | K24: =SUM(K4:K23) -> 25876.91
A25: Investing Activities
A26: Purchases of investment securities available-for-sale | B26: -220 | C26: -389 | D26: -267 | E26: -300 | F26: -508 | G26: =Table3[[#This Row],[2024]]*1.05 -> -533.4 | H26: =Table3[[#This Row],[2025E]]*1.05 -> -560.07 | I26: =Table3[[#This Row],[2026E]]*1.05 -> -588.0735 | J26: =Table3[[#This Row],[2027E]]*1.05 -> -617.47718 | K26: =Table3[[#This Row],[2028E]]*1.05 -> -648.35103
A27: Purchases of investments held-to-maturity | B27: -198 | C27: -294 | D27: -239 | E27: -347 | F27: -108 | G27: =Table3[[#This Row],[2024]]*1.05 -> -113.4 | H27: =Table3[[#This Row],[2025E]]*1.05 -> -119.07 | I27: =Table3[[#This Row],[2026E]]*1.05 -> -125.0235 | J27: =Table3[[#This Row],[2027E]]*1.05 -> -131.27468 | K27: =Table3[[#This Row],[2028E]]*1.05 -> -137.83841
A28: Proceeds from sales of investment securities available-for-sale | B28: 361 | C28: 83 | D28: 54 | E28: 87 | F28: 199 | G28: =Table3[[#This Row],[2024]]*1.05 -> 208.95 | H28: =Table3[[#This Row],[2025E]]*1.05 -> 219.3975 | I28: =Table3[[#This Row],[2026E]]*1.05 -> 230.36738 | J28: =Table3[[#This Row],[2027E]]*1.05 -> 241.88574 | K28: =Table3[[#This Row],[2028E]]*1.05 -> 253.98003
A29: Proceeds from maturities of investment securities available-for-sale | B29: 140 | C29: 291 | D29: 211 | E29: 191 | F29: 262 | G29: =Table3[[#This Row],[2024]]*1.05 -> 275.1 | H29: =Table3[[#This Row],[2025E]]*1.05 -> 288.855 | I29: =Table3[[#This Row],[2026E]]*1.05 -> 303.29775 | J29: =Table3[[#This Row],[2027E]]*1.05 -> 318.46264 | K29: =Table3[[#This Row],[2028E]]*1.05 -> 334.38577
A30: Proceeds from maturities of investments held-to-maturity | B30: 121 | C30: 296 | D30: 265 | E30: 157 | F30: 378 | G30: =Table3[[#This Row],[2024]]*1.05 -> 396.9 | H30: =Table3[[#This Row],[2025E]]*1.05 -> 416.745 | I30: =Table3[[#This Row],[2026E]]*1.05 -> 437.58225 | J30: =Table3[[#This Row],[2027E]]*1.05 -> 459.46136 | K30: =Table3[[#This Row],[2028E]]*1.05 -> 482.43443
A31: Purchases of property and equipment | B31: -339 | C31: -407 | D31: -442 | E31: -371 | F31: -474 | G31: =Table3[[#This Row],[2024]]*1.05 -> -497.7 | H31: =Table3[[#This Row],[2025E]]*1.05 -> -522.585 | I31: =Table3[[#This Row],[2026E]]*1.05 -> -548.71425 | J31: =Table3[[#This Row],[2027E]]*1.05 -> -576.14996 | K31: =Table3[[#This Row],[2028E]]*1.05 -> -604.95746
A32: Capitalized software | B32: -369 | C32: -407 | D32: -655 | E32: -717 | F32: -720 | G32: =Table3[[#This Row],[2024]]*1.05 -> -756 | H32: =Table3[[#This Row],[2025E]]*1.05 -> -793.8 | I32: =Table3[[#This Row],[2026E]]*1.05 -> -833.49 | J32: =Table3[[#This Row],[2027E]]*1.05 -> -875.1645 | K32: =Table3[[#This Row],[2028E]]*1.05 -> -918.92273
A33: Purchases of equity investments | B33: -214 | C33: -228 | D33: -88 | E33: -89 | F33: -42 | G33: =Table3[[#This Row],[2024]]*1.05 -> -44.1 | H33: =Table3[[#This Row],[2025E]]*1.05 -> -46.305 | I33: =Table3[[#This Row],[2026E]]*1.05 -> -48.62025 | J33: =Table3[[#This Row],[2027E]]*1.05 -> -51.051263 | K33: =Table3[[#This Row],[2028E]]*1.05 -> -53.603826
A34: Proceeds from sales of equity investments | B34: 0 | C34: 186 | D34: 7 | E34: 44 | F34: 125 | G34: =Table3[[#This Row],[2024]]*1.05 -> 131.25 | H34: =Table3[[#This Row],[2025E]]*1.05 -> 137.8125 | I34: =Table3[[#This Row],[2026E]]*1.05 -> 144.70312 | J34: =Table3[[#This Row],[2027E]]*1.05 -> 151.93828 | K34: =Table3[[#This Row],[2028E]]*1.05 -> 159.5352
A35: Acquisition of businesses, net of cash acquired | B35: -989 | C35: -4436 | D35: -313 | E35: 0 | F35: -2511 | G35: 0 | H35: 0 | I35: 0 | J35: 0 | K35: 0
A36: Settlement of interest rate derivative contracts | B36: -175 | C36: 0 | D36: 0 | E36: 0 | F36: 0 | G36: 0 | H36: 0 | I36: 0 | J36: 0 | K36: 0
A37: Other investing activities | B37: 3 | C37: 33 | D37: -3 | E37: -6 | F37: -3 | G37: -3 | H37: -3 | I37: -3 | J37: -3 | K37: -3
A38: Net cash used in investing activities | B38: -1879 | C38: -5272 | D38: -1470 | E38: -1351 | F38: -3402 | G38: =SUM(G26:G37) -> -935.4 | H38: =SUM(H26:H37) -> -982.02 | I38: =SUM(I26:I37) -> -1030.971 | J38: =SUM(J26:J37) -> -1082.3696 | K38: =SUM(K26:K37) -> -1136.338
A39: Financing Activities
A40: Purchases of treasury stock | B40: -4473 | C40: -5904 | D40: -8753 | E40: -9032 | F40: -11035 | G40: =Table3[[#This Row],[2024]]*1.07 -> -11807.45 | H40: =Table3[[#This Row],[2025E]]*1.07 -> -12633.972 | I40: =Table3[[#This Row],[2026E]]*1.07 -> -13518.35 | J40: =Table3[[#This Row],[2027E]]*1.07 -> -14464.634 | K40: =Table3[[#This Row],[2028E]]*1.07 -> -15477.158
...

Sheet Common Size
A1: Common Size Income Statement – Mastercard | B1: 2020 | C1: 2021 | D1: 2022 | E1: 2023 | F1: 2024 | G1: 2025 | H1: 2026 | I1: 2027 | J1: 2028 | K1: 2029
A2: Variables | B2: 2020 | C2: 2021 | D2: 2022 | E2: 2023 | F2: 2024 | G2: 2025E | H2: 2026E | I2: 2027E | J2: 2028E | K2: 2029E | L2: Item | M2: 2025 | N2: 2026 | O2: 2027 | P2: 2028 | Q2: 2029
A3: Net Revenue | B3: ='Profit Loss'!B4/'Profit Loss'!B4 -> 1 | C3: ='Profit Loss'!C4/'Profit Loss'!C4 -> 1 | D3: ='Profit Loss'!D4/'Profit Loss'!D4 -> 1 | E3: ='Profit Loss'!E4/'Profit Loss'!E4 -> 1 | F3: ='Profit Loss'!F4/'Profit Loss'!F4 -> 1 | G3: ='Profit Loss'!G4/'Profit Loss'!G4 -> 1 | H3: ='Profit Loss'!H4/'Profit Loss'!H4 -> 1 | I3: ='Profit Loss'!I4/'Profit Loss'!I4 -> 1 | ... K3: ='Profit Loss'!K4/'Profit Loss'!K4 -> 1 | L3: Revenue Growth | M3: 0.12 | N3: 0.11 | O3: 0.1 | P3: 0.09 | Q3: 0.08
A4: General & Administrative | B4: ='Profit Loss'!B6/Table1[[#This Row],[2020]] -> 0.38624926 | C4: =Table10[[#This Row],[2020]]*(1+2%) -> 0.39397425 | D4: =Table10[[#This Row],[2021]]*(1+2%) -> 0.40185374 | E4: =Table10[[#This Row],[2022]]*(1+2%) -> 0.40989081 | F4: =Table10[[#This Row],[2023]]*(1+2%) -> 0.41808863 | G4: =G3*Table35[[#This Row],[2025]] -> 0.42 | H4: =H3*Table35[[#This Row],[2026]] -> 0.425 | I4: =I3*Table35[[#This Row],[2027]] -> 0.43 | J4: =J3*Table35[[#This Row],[2028]] -> 0.43 | K4: =K3*Table35[[#This Row],[2029]] -> 0.43 | L4: G&A % | M4: 0.42 | N4: 0.425 | O4: 0.43 | P4: 0.43 | Q4: 0.43
A5: Advertising & Marketing | B5: ='Profit Loss'!B7/'Profit Loss'!B4 -> 0.04293837 | C5: ='Profit Loss'!C7/'Profit Loss'!C4 -> 0.04739462 | D5: ='Profit Loss'!D7/'Profit Loss'!D4 -> 0.035481405 | E5: ='Profit Loss'!E7/'Profit Loss'!E4 -> 0.032871145 | F5: ='Profit Loss'!F7/'Profit Loss'!F4 -> 0.028934569 | G5: =Table35[[#This Row],[2025]] -> 0.03 | H5: =Table35[[#This Row],[2025]] -> 0.03 | I5: =Table35[[#This Row],[2025]] -> 0.03 | J5: =Table35[[#This Row],[2025]] -> 0.03 | K5: =Table35[[#This Row],[2025]] -> 0.03 | L5: Marketing % | M5: 0.03 | N5: 0.03 | O5: 0.03 | P5: 0.03 | Q5: 0.03
A6: Depreciation & Amortization | B6: ='Profit Loss'!B8/'Profit Loss'!B4 -> 0.037906019 | C6: ='Profit Loss'!C8/'Profit Loss'!C4 -> 0.038445245 | D6: ='Profit Loss'!D8/'Profit Loss'!D4 -> 0.033727571 | E6: ='Profit Loss'!E8/'Profit Loss'!E4 -> 0.031835206 | F6: ='Profit Loss'!F8/'Profit Loss'!F4 -> 0.031845777 | G6: =Table35[[#This Row],[2025]] -> 0.03 | H6: =Table35[[#This Row],[2025]] -> 0.03 | I6: =Table35[[#This Row],[2025]] -> 0.03 | J6: =Table35[[#This Row],[2025]] -> 0.03 | K6: =Table35[[#This Row],[2025]] -> 0.03 | L6: Depreciation % | M6: 0.03 | N6: 0.029 | O6: 0.028 | P6: 0.027 | Q6: 0.026
A7: Provision for Litigation | B7: ='Profit Loss'!B9/'Profit Loss'!B4 -> 0.00477093 | C7: ='Profit Loss'!C9/'Profit Loss'!C4 -> 0.0049777589 | D7: ='Profit Loss'!D9/'Profit Loss'!D4 -> 0.016009354 | E7: ='Profit Loss'!E9/'Profit Loss'!E4 -> 0.021475815 | F7: ='Profit Loss'!F9/'Profit Loss'!F4 -> 0.024141726 | G7: ='Profit Loss'!G9/'Profit Loss'!G4 -> 0.022836768 | H7: ='Profit Loss'!H9/'Profit Loss'!H4 -> 0.021798733 | I7: ='Profit Loss'!I9/'Profit Loss'!I4 -> 0.02099878 | ... K7: ='Profit Loss'!K9/'Profit Loss'!K4 -> 0.020033882 | L7: Capex % | M7: 0.05 | N7: 0.05 | O7: 0.05 | P7: 0.05 | Q7: 0.05
A8: Total Operating Expenses | B8: ='Profit Loss'!B10/'Profit Loss'!B4 -> 0.47186458 | C8: ='Profit Loss'!C10/'Profit Loss'!C4 -> 0.46610888 | D8: ='Profit Loss'!D10/'Profit Loss'!D4 -> 0.44848676 | E8: ='Profit Loss'!E10/'Profit Loss'!E4 -> 0.44186788 | F8: ='Profit Loss'!F10/'Profit Loss'!F4 -> 0.44679945 | G8: ='Profit Loss'!G10/'Profit Loss'!G4 -> 0.45 | H8: ='Profit Loss'!H10/'Profit Loss'!H4 -> 0.44 | I8: ='Profit Loss'!I10/'Profit Loss'!I4 -> 0.435 | ... K8: ='Profit Loss'!K10/'Profit Loss'!K4 -> 0.425 | L8: Working Capital % | M8: 0.04 | N8: 0.04 | O8: 0.04 | P8: 0.04 | Q8: 0.04
A9: Operating Income | B9: ='Profit Loss'!B11/'Profit Loss'!B4 -> 0.52813542 | C9: ='Profit Loss'!C11/'Profit Loss'!C4 -> 0.53389112 | D9: ='Profit Loss'!D11/'Profit Loss'!D4 -> 0.55151324 | E9: ='Profit Loss'!E11/'Profit Loss'!E4 -> 0.55813212 | F9: ='Profit Loss'!F11/'Profit Loss'!F4 -> 0.55320055 | G9: ='Profit Loss'!G11/'Profit Loss'!G4 -> 0.55 | H9: ='Profit Loss'!H11/'Profit Loss'!H4 -> 0.56 | I9: ='Profit Loss'!I11/'Profit Loss'!I4 -> 0.565 | ... K9: ='Profit Loss'!K11/'Profit Loss'!K4 -> 0.575 | L9: Cash % of Assets | M9: 0.3 | N9: 0.32 | O9: 0.33 | P9: 0.34 | Q9: 0.35
A10: Investment Income | B10: ='Profit Loss'!B13/'Profit Loss'!B4 -> 0.0015685249 | C10: ='Profit Loss'!C13/'Profit Loss'!C4 -> 0.00058250371 | D10: ='Profit Loss'!D13/'Profit Loss'!D4 -> 0.0027431758 | E10: ='Profit Loss'!E13/'Profit Loss'!E4 -> 0.010917205 | F10: ='Profit Loss'!F13/'Profit Loss'!F4 -> 0.01160933 | G10: ='Profit Loss'!G13/'Profit Loss'!G4 -> 0.01087721 | H10: ='Profit Loss'!H13/'Profit Loss'!H4 -> 0.010283908 | I10: ='Profit Loss'!I13/'Profit Loss'!I4 -> 0.0098121689 | ... K10: ='Profit Loss'!K13/'Profit Loss'!K4 -> 0.0091838369 | L10: Interest Rate | M10: 0.035 | N10: 0.035 | O10: 0.035 | P10: 0.035 | Q10: 0.035
A11: Interest Expense | B11: ='Profit Loss'!B15/'Profit Loss'!B4 -> -0.024834978 | C11: ='Profit Loss'!C15/'Profit Loss'!C4 -> -0.022823554 | D11: ='Profit Loss'!D15/'Profit Loss'!D4 -> -0.021180915 | E11: ='Profit Loss'!E15/'Profit Loss'!E4 -> -0.022910192 | F11: ='Profit Loss'!F15/'Profit Loss'!F4 -> -0.02293464 | G11: ='Profit Loss'!G15/'Profit Loss'!G4 -> -0.026232538 | H11: ='Profit Loss'!H15/'Profit Loss'!H4 -> -0.023847762 | I11: ='Profit Loss'!I15/'Profit Loss'!I4 -> -0.02187868 | ... K11: ='Profit Loss'!K15/'Profit Loss'!K4 -> -0.018932745 | L11: Tax Rate | M11: 0.16 | N11: 0.16 | O11: 0.16 | P11: 0.16 | Q11: 0.16
A12: Total Other Income | B12: ='Profit Loss'!B17/'Profit Loss'!B4 -> -0.020979021 | C12: ='Profit Loss'!C17/'Profit Loss'!C4 -> 0.011914849 | D12: ='Profit Loss'!D17/'Profit Loss'!D4 -> -0.02392409 | E12: ='Profit Loss'!E17/'Profit Loss'!E4 -> -0.014702367 | F12: ='Profit Loss'!F17/'Profit Loss'!F4 -> -0.011644833 | G12: ='Profit Loss'!G17/'Profit Loss'!G4 -> -0.015355328 | H12: ='Profit Loss'!H17/'Profit Loss'!H4 -> -0.013563854 | I12: ='Profit Loss'!I17/'Profit Loss'!I4 -> -0.012066511 | ... K12: ='Profit Loss'!K17/'Profit Loss'!K4 -> -0.0097489084
A13: Income Before Tax | B13: ='Profit Loss'!B18/'Profit Loss'!B4 -> 0.5071564 | C13: ='Profit Loss'!C18/'Profit Loss'!C4 -> 0.54580597 | D13: ='Profit Loss'!D18/'Profit Loss'!D4 -> 0.52758915 | E13: ='Profit Loss'!E18/'Profit Loss'!E4 -> 0.54342976 | F13: ='Profit Loss'!F18/'Profit Loss'!F4 -> 0.54155572 | G13: ='Profit Loss'!G18/'Profit Loss'!G4 -> 0.53464467 | H13: ='Profit Loss'!H18/'Profit Loss'!H4 -> 0.54643615 | I13: ='Profit Loss'!I18/'Profit Loss'!I4 -> 0.55293349 | ... K13: ='Profit Loss'!K18/'Profit Loss'!K4 -> 0.56525109 | M13: 2020-2024 | N13: Historicals
A14: Income Tax Expense | B14: ='Profit Loss'!B19/'Profit Loss'!B4 -> 0.088164172 | C14: ='Profit Loss'!C19/'Profit Loss'!C4 -> 0.08578691 | D14: ='Profit Loss'!D19/'Profit Loss'!D4 -> 0.081036111 | E14: ='Profit Loss'!E19/'Profit Loss'!E4 -> 0.097378277 | F14: ='Profit Loss'!F19/'Profit Loss'!F4 -> 0.084496041 | G14: ='Profit Loss'!G19/'Profit Loss'!G4 -> 0.085543148 | H14: ='Profit Loss'!H19/'Profit Loss'!H4 -> 0.087429783 | I14: ='Profit Loss'!I19/'Profit Loss'!I4 -> 0.088469358 | ... K14: ='Profit Loss'!K19/'Profit Loss'!K4 -> 0.090440175 | M14: 2025-2029 | N14: Projections
A15: Net Income | B15: ='Profit Loss'!B20/'Profit Loss'!B4 -> 0.41899222 | C15: ='Profit Loss'!C20/'Profit Loss'!C4 -> 0.46001906 | D15: ='Profit Loss'!D20/'Profit Loss'!D4 -> 0.44655304 | E15: ='Profit Loss'!E20/'Profit Loss'!E4 -> 0.44605148 | F15: ='Profit Loss'!F20/'Profit Loss'!F4 -> 0.45705968 | G15: ='Profit Loss'!G20/'Profit Loss'!G4 -> 0.44910152 | H15: ='Profit Loss'!H20/'Profit Loss'!H4 -> 0.45900636 | I15: ='Profit Loss'!I20/'Profit Loss'!I4 -> 0.46446413 | ... K15: ='Profit Loss'!K20/'Profit Loss'!K4 -> 0.47481092
A16: EBITDA | B16: ='Profit Loss'!B25/'Profit Loss'!B4 -> 0.56604144 | C16: ='Profit Loss'!C25/'Profit Loss'!C4 -> 0.57233637 | D16: ='Profit Loss'!D25/'Profit Loss'!D4 -> 0.58524081 | E16: ='Profit Loss'!E25/'Profit Loss'!E4 -> 0.58996733 | F16: ='Profit Loss'!F25/'Profit Loss'!F4 -> 0.58504633 | G16: ='Profit Loss'!G25/'Profit Loss'!G4 -> 0.58098508 | H16: ='Profit Loss'!H25/'Profit Loss'!H4 -> 0.59042172 | I16: ='Profit Loss'!I25/'Profit Loss'!I4 -> 0.59514262 | ... K16: ='Profit Loss'!K25/'Profit Loss'!K4 -> 0.60542432
A18: Common Size Balance Sheet – Mastercard | B18: 2020 | C18: 2021 | D18: 2022 | E18: 2023 | F18: 2024 | G18: 2025 | H18: 2026 | I18: 2027 | J18: 2028 | K18: 2029
A19: Variables | B19: 2020 | C19: 2021 | D19: 2022 | E19: 2023 | F19: 2024 | G19: 2025E | H19: 2026E | I19: 2027E | J19: 2028E | K19: 2029E
A20: Cash & Cash Equivalents | B20: =Balance_Sheet!B4/Balance_Sheet!B18 -> 0.30112554 | C20: =Balance_Sheet!C4/Balance_Sheet!C18 -> 0.1970055 | D20: =Balance_Sheet!D4/Balance_Sheet!D18 -> 0.18097304 | E20: =Balance_Sheet!E4/Balance_Sheet!E18 -> 0.20231813 | F20: =Balance_Sheet!F4/Balance_Sheet!F18 -> 0.17557871 | G20: =M9 -> 0.3 | H20: =N9 -> 0.32 | I20: =O9 -> 0.33 | J20: =P9 -> 0.34 | K20: =Q9 -> 0.35
A21: Accounts Receivable | B21: =Balance_Sheet!B7/Balance_Sheet!B18 -> 0.078787518 | C21: =Balance_Sheet!C7/Balance_Sheet!C18 -> 0.079800366 | D21: =Balance_Sheet!D7/Balance_Sheet!D18 -> 0.088446441 | E21: =Balance_Sheet!E7/Balance_Sheet!E18 -> 0.013946476 | F21: =Balance_Sheet!F7/Balance_Sheet!F18 -> 0.006863418 | G21: =Balance_Sheet!G7/Balance_Sheet!G18 -> 0.0062318024 | H21: =Balance_Sheet!H7/Balance_Sheet!H18 -> 0.0057047204 | I21: =Balance_Sheet!I7/Balance_Sheet!I18 -> 0.0052553076 | ... K21: =Balance_Sheet!K7/Balance_Sheet!K18 -> 0.0045136326
A22: Settlement Assets | B22: =Balance_Sheet!B8/Balance_Sheet!B18 -> 0.050797999 | C22: =Balance_Sheet!C8/Balance_Sheet!C18 -> 0.03501553 | D22: =Balance_Sheet!D8/Balance_Sheet!D18 -> 0.032796199 | E22: =Balance_Sheet!E8/Balance_Sheet!E18 -> 0.095646438 | F22: =Balance_Sheet!F8/Balance_Sheet!F18 -> 0.078471746 | G22: =Balance_Sheet!G8/Balance_Sheet!G18 -> 0.07137278 | H22: =Balance_Sheet!H8/Balance_Sheet!H18 -> 0.065336114 | I22: =Balance_Sheet!I8/Balance_Sheet!I18 -> 0.060188994 | ... K22: =Balance_Sheet!K8/Balance_Sheet!K18 -> 0.051694596
A23: Total Current Assets | B23: =SUM(B20:B22) -> 0.43071105 | C23: =SUM(C20:C22) -> 0.31182139 | D23: =SUM(D20:D22) -> 0.30221568 | E23: =SUM(E20:E22) -> 0.31191104 | F23: =SUM(F20:F22) -> 0.26091387 | G23: =SUM(G20:G22) -> 0.37760458 | H23: =SUM(H20:H22) -> 0.39104083 | I23: =SUM(I20:I22) -> 0.3954443 | ... K23: =SUM(K20:K22) -> 0.40620823
A24: PPE | B24: =Balance_Sheet!B12/Balance_Sheet!B18 -> 0.056634111 | C24: =Balance_Sheet!C12/Balance_Sheet!C18 -> 0.050625183 | D24: =Balance_Sheet!D12/Balance_Sheet!D18 -> 0.0518025 | E24: =Balance_Sheet!E12/Balance_Sheet!E18 -> 0.048553524 | F24: =Balance_Sheet!F12/Balance_Sheet!F18 -> 0.044466629 | G24: =Balance_Sheet!G12/Balance_Sheet!G18 -> 0.037879591 | H24: =Balance_Sheet!H12/Balance_Sheet!H18 -> 0.032784353 | I24: =Balance_Sheet!I12/Balance_Sheet!I18 -> 0.028816236 | ... K24: =Balance_Sheet!K12/Balance_Sheet!K18 -> 0.023164581
A25: Intangible Assets | B25: =Balance_Sheet!B14/Balance_Sheet!B18 -> 0.14768938 | C25: =Balance_Sheet!C14/Balance_Sheet!C18 -> 0.20340333 | D25: =Balance_Sheet!D14/Balance_Sheet!D18 -> 0.19424646 | E25: =Balance_Sheet!E14/Balance_Sheet!E18 -> 0.18045609 | F25: =Balance_Sheet!F14/Balance_Sheet!F18 -> 0.19119819 | G25: =Balance_Sheet!G14/Balance_Sheet!G18 -> 0.15661073 | H25: =Balance_Sheet!H14/Balance_Sheet!H18 -> 0.13033153 | I25: =Balance_Sheet!I14/Balance_Sheet!I18 -> 0.11015058 | ... K25: =Balance_Sheet!K14/Balance_Sheet!K18 -> 0.081866706
A26: Other Assets | B26: =Balance_Sheet!B17/Balance_Sheet!B18 -> 0.15974869 | C26: =Balance_Sheet!C17/Balance_Sheet!C18 -> 0.18566991 | D26: =Balance_Sheet!D17/Balance_Sheet!D18 -> 0.19574424 | E26: =Balance_Sheet!E17/Balance_Sheet!E18 -> 0.19612231 | F26: =Balance_Sheet!F17/Balance_Sheet!F18 -> 0.20712964 | G26: =Balance_Sheet!G17/Balance_Sheet!G18 -> 0.18828565 | H26: =Balance_Sheet!H17/Balance_Sheet!H18 -> 0.17236057 | I26: =Balance_Sheet!I17/Balance_Sheet!I18 -> 0.15878216 | ... K26: =Balance_Sheet!K17/Balance_Sheet!K18 -> 0.13637343
A27: Total Assets | B27: 1 | C27: 1 | D27: 1 | E27: 1 | F27: 1 | G27: 1 | H27: 1 | I27: 1 | J27: 1 | K27: 1
A28: Liabilities
A29: Accounts Payable | B29: =Balance_Sheet!B20/Balance_Sheet!B18 -> 0.015691996 | C29: =Balance_Sheet!C20/Balance_Sheet!C18 -> 0.019591707 | D29: =Balance_Sheet!D20/Balance_Sheet!D18 -> 0.023912819 | E29: =Balance_Sheet!E20/Balance_Sheet!E18 -> 0.019647569 | F29: =Balance_Sheet!F20/Balance_Sheet!F18 -> 0.019321562 | G29: =Balance_Sheet!G20/Balance_Sheet!G18 -> 0.017576879 | H29: =Balance_Sheet!H20/Balance_Sheet!H18 -> 0.016090237 | I29: =Balance_Sheet!I20/Balance_Sheet!I18 -> 0.014822663 | ... K29: =Balance_Sheet!K20/Balance_Sheet!K18 -> 0.012730759
A30: Settlement Obligations | B30: =Balance_Sheet!B21/Balance_Sheet!B18 -> 0.043919724 | C30: =Balance_Sheet!C21/Balance_Sheet!C18 -> 0.024237437 | D30: =Balance_Sheet!D21/Balance_Sheet!D18 -> 0.028690218 | E30: =Balance_Sheet!E21/Balance_Sheet!E18 -> 0.032957972 | F30: =Balance_Sheet!F21/Balance_Sheet!F18 -> 0.048168715 | G30: =Balance_Sheet!G21/Balance_Sheet!G18 -> 0.04367588 | H30: =Balance_Sheet!H21/Balance_Sheet!H18 -> 0.039981801 | I30: =Balance_Sheet!I21/Balance_Sheet!I18 -> 0.036832071 | ... K30: =Balance_Sheet!K21/Balance_Sheet!K18 -> 0.031634007
A31: Accrued Expenses | B31: =Balance_Sheet!B24/Balance_Sheet!B18 -> 0.16168414 | C31: =Balance_Sheet!C24/Balance_Sheet!C18 -> 0.17632536 | D31: =Balance_Sheet!D24/Balance_Sheet!D18 -> 0.2014513 | E31: =Balance_Sheet!E24/Balance_Sheet!E18 -> 0.2006455 | F31: =Balance_Sheet!F24/Balance_Sheet!F18 -> 0.21615607 | G31: =Balance_Sheet!G24/Balance_Sheet!G18 -> 0.19654146 | H31: =Balance_Sheet!H24/Balance_Sheet!H18 -> 0.1799181 | I31: =Balance_Sheet!I24/Balance_Sheet!I18 -> 0.16574432 | ... K31: =Balance_Sheet!K24/Balance_Sheet!K18 -> 0.14235303
A32: Other Current Liabilities | B32: =Balance_Sheet!B26/Balance_Sheet!B18 -> 0.036565031 | C32: =Balance_Sheet!C26/Balance_Sheet!C18 -> 0.036210146 | D32: =Balance_Sheet!D26/Balance_Sheet!D18 -> 0.036075819 | E32: =Balance_Sheet!E26/Balance_Sheet!E18 -> 0.037905202 | F32: =Balance_Sheet!F26/Balance_Sheet!F18 -> 0.042178823 | G32: =Balance_Sheet!G26/Balance_Sheet!G18 -> 0.038349553 | H32: =Balance_Sheet!H26/Balance_Sheet!H18 -> 0.035105971 | I32: =Balance_Sheet!I26/Balance_Sheet!I18 -> 0.032340355 | ... K32: =Balance_Sheet!K26/Balance_Sheet!K18 -> 0.027776201
A33: Total Current Liabilities | B33: =Balance_Sheet!B27/Balance_Sheet!B18 -> 0.35275727 | C33: =Balance_Sheet!C27/Balance_Sheet!C18 -> 0.34941198 | D33: =Balance_Sheet!D27/Balance_Sheet!D18 -> 0.36594877 | E33: =Balance_Sheet!E27/Balance_Sheet!E18 -> 0.38315115 | F33: =Balance_Sheet!F27/Balance_Sheet!F18 -> 0.3997421 | G33: =Balance_Sheet!G27/Balance_Sheet!G18 -> 0.35668924 | H33: =Balance_Sheet!H27/Balance_Sheet!H18 -> 0.32148209 | I33: =Balance_Sheet!I27/Balance_Sheet!I18 -> 0.29232345 | ... K33: =Balance_Sheet!K27/Balance_Sheet!K18 -> 0.24614354
A34: Long-Term Debt | B34: =Balance_Sheet!B28/Balance_Sheet!B18 -> 0.35799786 | C34: =Balance_Sheet!C28/Balance_Sheet!C18 -> 0.34800499 | D34: =Balance_Sheet!D28/Balance_Sheet!D18 -> 0.35505113 | E34: =Balance_Sheet!E28/Balance_Sheet!E18 -> 0.33791934 | F34: =Balance_Sheet!F28/Balance_Sheet!F18 -> 0.36346998 | G34: =Balance_Sheet!G28/Balance_Sheet!G18 -> 0.29771881 | H34: =Balance_Sheet!H28/Balance_Sheet!H18 -> 0.24776176 | I34: =Balance_Sheet!I28/Balance_Sheet!I18 -> 0.20939753 | ... K34: =Balance_Sheet!K28/Balance_Sheet!K18 -> 0.15562956
A35: Deferred Taxes | B35: =Balance_Sheet!B29/Balance_Sheet!B18 -> 0.0025607432 | C35: =Balance_Sheet!C29/Balance_Sheet!C18 -> 0.010486076 | D35: =Balance_Sheet!D29/Balance_Sheet!D18 -> 0.010148745 | E35: =Balance_Sheet!E29/Balance_Sheet!E18 -> 0.0086929891 | F35: =Balance_Sheet!F29/Balance_Sheet!F18 -> 0.0065930409 | G35: =Balance_Sheet!G29/Balance_Sheet!G18 -> 0.0054003698 | H35: =Balance_Sheet!H29/Balance_Sheet!H18 -> 0.0044941908 | I35: =Balance_Sheet!I29/Balance_Sheet!I18 -> 0.0037982959 | ... K35: =Balance_Sheet!K29/Balance_Sheet!K18 -> 0.0028229899
A36: Total Liabilities | B36: =Balance_Sheet!B31/Balance_Sheet!B18 -> 0.80594926 | C36: =Balance_Sheet!C31/Balance_Sheet!C18 -> 0.80323343 | D36: =Balance_Sheet!D31/Balance_Sheet!D18 -> 0.83532176 | E36: =Balance_Sheet!E31/Balance_Sheet!E18 -> 0.83516302 | F36: =Balance_Sheet!F31/Balance_Sheet!F18 -> 0.86449949 | G36: =Balance_Sheet!G31/Balance_Sheet!G18 -> 0.7459048 | H36: =Balance_Sheet!H31/Balance_Sheet!H18 -> 0.65255244 | I36: =Balance_Sheet!I31/Balance_Sheet!I18 -> 0.57812475 | ... K36: =Balance_Sheet!K31/Balance_Sheet!K18 -> 0.46695484
A37: Total Equity | B37: =Balance_Sheet!B41/Balance_Sheet!B18 -> 0.19318723 | C37: =Balance_Sheet!C41/Balance_Sheet!C18 -> 0.19599671 | D37: =Balance_Sheet!D41/Balance_Sheet!D18 -> 0.16413594 | E37: =Balance_Sheet!E41/Balance_Sheet!E18 -> 0.1643187 | F37: =Balance_Sheet!F41/Balance_Sheet!F18 -> 0.13550051 | G37: =Balance_Sheet!G41/Balance_Sheet!G18 -> 0.2540952 | H37: =Balance_Sheet!H41/Balance_Sheet!H18 -> 0.34744756 | I37: =Balance_Sheet!I41/Balance_Sheet!I18 -> 0.42187525 | ... K37: =Balance_Sheet!K41/Balance_Sheet!K18 -> 0.53304516
A39: Asset Turnover Ratio | B39: 2020 | C39: 2021 | D39: 2022 | E39: 2023 | F39: 2024 | G39: 2025E | H39: 2026E | I39: 2027E | J39: 2028E | K39: 2029E
A40: Sales / Total Assets | B40: ='Profit Loss'!B4/Balance_Sheet!B18 -> 0.45560386 | C40: ='Profit Loss'!C4/Balance_Sheet!C18 -> 0.50131408 | D40: ='Profit Loss'!D4/Balance_Sheet!D18 -> 0.57424336 | E40: ='Profit Loss'!E4/Balance_Sheet!E18 -> 0.59126461 | F40: ='Profit Loss'!F4/Balance_Sheet!F18 -> 0.58582392 | G40: ='Profit Loss'!G4/Balance_Sheet!G18 -> 0.53263268 | H40: ='Profit Loss'!H4/Balance_Sheet!H18 -> 0.48758294 | I40: ='Profit Loss'!I4/Balance_Sheet!I18 -> 0.44917159 | ... K40: ='Profit Loss'!K4/Balance_Sheet!K18 -> 0.38578057
A42: Debt Scheduling | B42: 2020 | C42: 2021 | D42: 2022 | E42: 2023 | F42: 2024 | G42: 2025E | H42: 2026E | I42: 2027E | J42: 2028E | K42: 2029E
A43: Total Debt | B43: =Balance_Sheet!B28+Balance_Sheet!B25 -> 12672 | C43: =Balance_Sheet!C28+Balance_Sheet!C25 -> 13901 | D43: =Balance_Sheet!D28+Balance_Sheet!D25 -> 14023 | E43: =Balance_Sheet!E28+Balance_Sheet!E25 -> 15681 | F43: =Balance_Sheet!F28+Balance_Sheet!F25 -> 18226 | G43: =Balance_Sheet!G28+Balance_Sheet!G25 -> 18226 | H43: =Balance_Sheet!H28+Balance_Sheet!H25 -> 18226 | I43: =Balance_Sheet!I28+Balance_Sheet!I25 -> 18226 | ... K43: =Balance_Sheet!K28+Balance_Sheet!K25 -> 18226
...

Sheet Ind_P&L
A1: Income Statement- USD ($) shares in Millions, $ in Millions | B1: 2020 | C1: 2021 | D1: 2022 | E1: 2023 | F1: 2024
A2: Mastercard Inc
A3: Net Revenue / Total Revenue | B3: 132310 | C3: 162672 | D3: 183399 | E3: 196337 | F3: 222366
A4: Operating Expenses
A5: General & Administrative | B5: 15843 | C5: 18675 | D5: 19642 | E5: 21409 | F5: 23108
A6: Advertising & Marketing | B6: 7324 | C6: 8067 | D6: 7560 | E6: 7213 | F6: 7416
A7: Depreciation & Amortization | B7: 3277 | C7: 3607 | D7: 3646 | E7: 3806 | F7: 4109
A8: Provision for Litigation | B8: 84 | C8: 97 | D8: 1224 | E8: 1466 | F8: 1142
A9: Total Operating Expenses | B9: 89910 | C9: 103424 | D9: 111197 | E9: 117306 | F9: 130026
A10: Operating Income | B10: 42400 | C10: 59248 | D10: 72202 | E10: 79031 | F10: 92340
A11: Other Income (Expense)
